<mujoco model="ant">
  <compiler angle="degree" coordinate="local" inertiafromgeom="true"/>
  <option integrator="RK4" timestep="0.01"/>
  <custom>
    <numeric data="0.0 0.0 0.55 1.0 0.0 0.0 0.0 0.0 1.0 0.0 -1.0 0.0 -1.0 0.0 1.0" name="init_qpos"/>
  </custom>
  <default>
    <joint armature="1" damping="1" limited="true"/>
    <geom conaffinity="0" condim="3" density="5.0" friction="1 0.5 0.5" margin="0.01" rgba="0.8 0.6 0.4 1"/>
    <default class="wall_start">
        <geom conaffinity="1" condim="3" density="5.0" friction="1 0.5 0.5" margin="0.01" type="box" rgba="0.630 0.411 0.0819 0.5" />
    </default>
    <default class="wall">
        <geom conaffinity="1" condim="3" density="5.0" friction="1 0.5 0.5" margin="0.01" type="box" rgba=".2 .3 .4 0.5" />
    </default>
    <default class="floor">
        <geom type="box" material="MatPlane" conaffinity="1" condim="3" group="2" rgba="0.8 0.9 0.8 1" />
    </default>
      <default class="floor_start">
        <geom type="box" material="MatPlane_start" conaffinity="1" condim="3" group="2" rgba="0.8 0.9 0.8 1" />
    </default>
  </default>
  <asset>
    <texture builtin="gradient" height="100" rgb1=".4 .5 .6" rgb2="0 0 0" type="skybox" width="100"/>
    <texture builtin="flat" height="1278" mark="cross" markrgb="1 1 1" name="texgeom" random="0.01" rgb1="0.8 0.6 0.4" rgb2="0.8 0.6 0.4" type="cube" width="127"/>
    <texture name="texplane" type="2d" builtin="checker" rgb1=".2 .3 .4" rgb2=".1 0.15 0.2" width="100" height="100"></texture>
    <texture name="texplane_start" type="2d" builtin="checker" rgb1="0.630 0.411 0.0819" rgb2="0.315 0.205 0.041" width="100" height="100"></texture>
    <material name="MatPlane" reflectance="0.5" texture="texplane" texrepeat="1 1" texuniform="true"></material>
    <material name="MatPlane_start" reflectance="0.5" texture="texplane_start" texrepeat="1 1" texuniform="true"></material>
    <material name="geom" texture="texgeom" texuniform="true"/>
  </asset>
  <worldbody>
    <light cutoff="100" diffuse="1 1 1" dir="-0 0 -1.3" directional="true" exponent="1" pos="0 0 1.3" specular=".1 .1 .1"/>
    <geom name="floor" pos="0 0 0" size="200 200 0.125" type="plane"  conaffinity="1" condim="3" group="2" rgba="0.0 0.0 0.0 0.0"></geom>


    <body name="start_tunnel">
      <geom class="wall_start" size="3 0.5 2" pos="2 -2 7"/>
      <geom class="wall_start" size="0.5 2.5 2" pos="-1.5 0 7"/>
      <geom class="wall_start" size="3 0.5 2" pos="2 2 7"/>
      <geom class="wall_start" size="0.5 2.25 2" pos="5.5 -3.75 7" />
      <geom class="wall_start" size="0.5 2.25 2" pos="5.5 3.75 7" />
      <geom class="floor_start" size="4 2.5 0.0125" pos="2 0 5" />
    </body>

    <body name="segments">
    </body>

<!--    <body name="seg1">-->
<!--      <geom class="floor" size="3 6 0.0125" pos="9 0 5" />-->
<!--      <geom class="floor" size="2 3 0.0125" pos="14 3 5"  />-->
<!--      <geom class="wall" size="5 0.5 2" pos="11 5.5 7" />-->
<!--      <geom class="wall" size="5 0.5 2" pos="11 -5.5 7" />-->
<!--      <geom class="wall" size="2 0.5 2" pos="14 0 7" />-->
<!--      <geom type="cylinder" size="0.2 3" euler="90 0 0" pos="12 -3 4.8125" rgba=".2 .3 .4 1"/>-->
<!--      <geom type="cylinder" size="0.2 3" euler="90 0 0" pos="16 -3 4.8125" rgba=".2 .3 .4 1"/>-->
<!--    </body>-->

<!--    <body name="seg2">-->
<!--      <geom class="floor" size="3 6 0.0125" pos="19 0 5" />-->
<!--      <geom class="floor" size="2 3 0.0125" pos="24 -3 5"  />-->
<!--      <geom class="wall" size="5 0.5 2" pos="21 5.5 7" />-->
<!--      <geom class="wall" size="5 0.5 2" pos="21 -5.5 7" />-->
<!--      <geom class="wall" size="2 0.5 2" pos="24 0 7" />-->
<!--      <geom type="cylinder" size="0.2 3" euler="90 0 0" pos="22 3 4.8125" rgba=".2 .3 .4 1"/>-->
<!--      <geom type="cylinder" size="0.2 3" euler="90 0 0" pos="26 3 4.8125" rgba=".2 .3 .4 1"/>-->
<!--    </body>-->

    
    <body name="torso" pos="0 0 5.75">
      <camera name="track" mode="trackcom" pos="0 -3 0.3" xyaxes="1 0 0 0 0 1"/>
      <geom name="torso_geom" pos="0 0 0" size="0.25" type="sphere"/>
      <joint armature="0" damping="0" limited="false" margin="0.01" name="root" pos="0 0 0" type="free"/>
      <body name="front_left_leg" pos="0 0 0">
        <geom fromto="0.0 0.0 0.0 0.2 0.2 0.0" name="aux_1_geom" size="0.08" type="capsule"/>
        <body name="aux_1" pos="0.2 0.2 0">
          <joint axis="0 0 1" name="hip_1" pos="0.0 0.0 0.0" range="-30 30" type="hinge"/>
          <geom fromto="0.0 0.0 0.0 0.2 0.2 0.0" name="left_leg_geom" size="0.08" type="capsule"/>
          <body pos="0.2 0.2 0">
            <joint axis="-1 1 0" name="ankle_1" pos="0.0 0.0 0.0" range="30 70" type="hinge"/>
            <geom fromto="0.0 0.0 0.0 0.4 0.4 0.0" name="left_ankle_geom" size="0.08" type="capsule"/>
          </body>
        </body>
      </body>
      <body name="front_right_leg" pos="0 0 0">
        <geom fromto="0.0 0.0 0.0 -0.2 0.2 0.0" name="aux_2_geom" size="0.08" type="capsule"/>
        <body name="aux_2" pos="-0.2 0.2 0">
          <joint axis="0 0 1" name="hip_2" pos="0.0 0.0 0.0" range="-30 30" type="hinge"/>
          <geom fromto="0.0 0.0 0.0 -0.2 0.2 0.0" name="right_leg_geom" size="0.08" type="capsule"/>
          <body pos="-0.2 0.2 0">
            <joint axis="1 1 0" name="ankle_2" pos="0.0 0.0 0.0" range="-70 -30" type="hinge"/>
            <geom fromto="0.0 0.0 0.0 -0.4 0.4 0.0" name="right_ankle_geom" size="0.08" type="capsule"/>
          </body>
        </body>
      </body>
      <body name="back_leg" pos="0 0 0">
        <geom fromto="0.0 0.0 0.0 -0.2 -0.2 0.0" name="aux_3_geom" size="0.08" type="capsule"/>
        <body name="aux_3" pos="-0.2 -0.2 0">
          <joint axis="0 0 1" name="hip_3" pos="0.0 0.0 0.0" range="-30 30" type="hinge"/>
          <geom fromto="0.0 0.0 0.0 -0.2 -0.2 0.0" name="back_leg_geom" size="0.08" type="capsule"/>
          <body pos="-0.2 -0.2 0">
            <joint axis="-1 1 0" name="ankle_3" pos="0.0 0.0 0.0" range="-70 -30" type="hinge"/>
            <geom fromto="0.0 0.0 0.0 -0.4 -0.4 0.0" name="third_ankle_geom" size="0.08" type="capsule"/>
          </body>
        </body>
      </body>
      <body name="right_back_leg" pos="0 0 0">
        <geom fromto="0.0 0.0 0.0 0.2 -0.2 0.0" name="aux_4_geom" size="0.08" type="capsule"/>
        <body name="aux_4" pos="0.2 -0.2 0">
          <joint axis="0 0 1" name="hip_4" pos="0.0 0.0 0.0" range="-30 30" type="hinge"/>
          <geom fromto="0.0 0.0 0.0 0.2 -0.2 0.0" name="rightback_leg_geom" size="0.08" type="capsule"/>
          <body pos="0.2 -0.2 0">
            <joint axis="1 1 0" name="ankle_4" pos="0.0 0.0 0.0" range="30 70" type="hinge"/>
            <geom fromto="0.0 0.0 0.0 0.4 -0.4 0.0" name="fourth_ankle_geom" size="0.08" type="capsule"/>
          </body>
        </body>
      </body>
    </body>
  </worldbody>
  <actuator>
    <motor ctrllimited="true" ctrlrange="-1.0 1.0" joint="hip_4" gear="150"/>
    <motor ctrllimited="true" ctrlrange="-1.0 1.0" joint="ankle_4" gear="150"/>
    <motor ctrllimited="true" ctrlrange="-1.0 1.0" joint="hip_1" gear="150"/>
    <motor ctrllimited="true" ctrlrange="-1.0 1.0" joint="ankle_1" gear="150"/>
    <motor ctrllimited="true" ctrlrange="-1.0 1.0" joint="hip_2" gear="150"/>
    <motor ctrllimited="true" ctrlrange="-1.0 1.0" joint="ankle_2" gear="150"/>
    <motor ctrllimited="true" ctrlrange="-1.0 1.0" joint="hip_3" gear="150"/>
    <motor ctrllimited="true" ctrlrange="-1.0 1.0" joint="ankle_3" gear="150"/>
  </actuator>
</mujoco>
